I'm sorry, but an uncaught exception occurred.

While running game code:
  File "game/script.rpy", line 27, in script
    e "You've created a new Ren'Py game."
Exception: Sayer 'e' is not defined.

-- Full Traceback ------------------------------------------------------------

Full traceback:
  File "game/script.rpy", line 27, in script
    e "You've created a new Ren'Py game."
  File "C:\Users\mayth\Downloads\renpy-6.99.14.2-sdk\renpy\ast.py", line 624, in execute
    who = eval_who(self.who, self.who_fast)
  File "C:\Users\mayth\Downloads\renpy-6.99.14.2-sdk\renpy\ast.py", line 537, in eval_who
    raise Exception("Sayer '%s' is not defined." % who.encode("utf-8"))
Exception: Sayer 'e' is not defined.

Windows-8-6.2.9200
Ren'Py 6.99.14.2.3333
project1 1.0
Fri Mar 30 13:33:13 2018
